{
 "cells": [
  {
   "cell_type": "code",
   "execution_count": 2,
   "metadata": {},
   "outputs": [
    {
     "name": "stdout",
     "output_type": "stream",
     "text": [
      "Collecting python-telegram-bot\n",
      "  Using cached https://files.pythonhosted.org/packages/26/aa/82dfedea526128a55429527ca5e43c023846e00cc3df30c8dbfebe94bbb2/python_telegram_bot-12.2.0-py2.py3-none-any.whl\n",
      "Requirement already satisfied: tornado>=5.1 in c:\\programdata\\anaconda3\\lib\\site-packages (from python-telegram-bot) (6.0.3)\n",
      "Requirement already satisfied: future>=0.16.0 in c:\\programdata\\anaconda3\\lib\\site-packages (from python-telegram-bot) (0.17.1)\n",
      "Requirement already satisfied: certifi in c:\\programdata\\anaconda3\\lib\\site-packages (from python-telegram-bot) (2019.9.11)\n",
      "Requirement already satisfied: cryptography in c:\\programdata\\anaconda3\\lib\\site-packages (from python-telegram-bot) (2.7)\n",
      "Requirement already satisfied: asn1crypto>=0.21.0 in c:\\programdata\\anaconda3\\lib\\site-packages (from cryptography->python-telegram-bot) (1.0.1)\n",
      "Requirement already satisfied: cffi!=1.11.3,>=1.8 in c:\\programdata\\anaconda3\\lib\\site-packages (from cryptography->python-telegram-bot) (1.12.3)\n",
      "Requirement already satisfied: six>=1.4.1 in c:\\programdata\\anaconda3\\lib\\site-packages (from cryptography->python-telegram-bot) (1.12.0)\n",
      "Requirement already satisfied: pycparser in c:\\programdata\\anaconda3\\lib\\site-packages (from cffi!=1.11.3,>=1.8->cryptography->python-telegram-bot) (2.19)\n",
      "Installing collected packages: python-telegram-bot\n",
      "Successfully installed python-telegram-bot-12.2.0\n"
     ]
    }
   ],
   "source": [
    "!pip install python-telegram-bot"
   ]
  },
  {
   "cell_type": "code",
   "execution_count": null,
   "metadata": {},
   "outputs": [],
   "source": [
    "#!/usr/bin/env python\n",
    "# -*- coding: utf-8 -*-\n",
    "# This program is dedicated to the public domain under the CC0 license.\n",
    "\n",
    "\"\"\"\n",
    "First, a few callback functions are defined. Then, those functions are passed to\n",
    "the Dispatcher and registered at their respective places.\n",
    "Then, the bot is started and runs until we press Ctrl-C on the command line.\n",
    "Usage:\n",
    "Example of a bot-user conversation using ConversationHandler.\n",
    "Send /start to initiate the conversation.\n",
    "Press Ctrl-C on the command line or send a signal to the process to stop the\n",
    "bot.\n",
    "\"\"\"\n",
    "\n",
    "import logging\n",
    "\n",
    "from telegram import ReplyKeyboardMarkup\n",
    "from telegram.ext import (Updater, CommandHandler, MessageHandler, Filters,\n",
    "                          ConversationHandler)\n",
    "\n",
    "# Enable logging\n",
    "logging.basicConfig(format='%(asctime)s - %(name)s - %(levelname)s - %(message)s',\n",
    "                    level=logging.INFO)\n",
    "\n",
    "logger = logging.getLogger(__name__)\n",
    "\n",
    "CHOOSING, TYPING_REPLY, TYPING_CHOICE = range(3)\n",
    "\n",
    "reply_keyboard = [['Age', 'Favourite colour'],\n",
    "                  ['Number of siblings', 'Something else...'],\n",
    "                  ['Done']]\n",
    "markup = ReplyKeyboardMarkup(reply_keyboard, one_time_keyboard=True)\n",
    "\n",
    "\n",
    "reply_keyboard_2 = [\"\"]\n",
    "def facts_to_str(user_data):\n",
    "    facts = list()\n",
    "\n",
    "    for key, value in user_data.items():\n",
    "        facts.append('{} - {}'.format(key, value))\n",
    "\n",
    "    return \"\\n\".join(facts).join(['\\n', '\\n'])\n",
    "\n",
    "\n",
    "def start(update, context):\n",
    "    update.message.reply_text(\n",
    "        \"Hi! My name is Doctor Botter. I will hold a more complex conversation with you. \"\n",
    "        \"Why don't you tell me something about yourself?\",\n",
    "        reply_markup=markup)\n",
    "\n",
    "    return CHOOSING\n",
    "\n",
    "\n",
    "def regular_choice(update, context):\n",
    "    text = update.message.text\n",
    "    context.user_data['choice'] = text\n",
    "    update.message.reply_text(\n",
    "        'Your {}? Yes, I would love to hear about that!'.format(text.lower()))\n",
    "\n",
    "    return TYPING_REPLY\n",
    "\n",
    "\n",
    "def custom_choice(update, context):\n",
    "    update.message.reply_text('Alright, please send me the category first, '\n",
    "                              'for example \"Most impressive skill\"')\n",
    "\n",
    "    return TYPING_CHOICE\n",
    "\n",
    "\n",
    "def received_information(update, context):\n",
    "    user_data = context.user_data\n",
    "    text = update.message.text\n",
    "    category = user_data['choice']\n",
    "    user_data[category] = text\n",
    "    del user_data['choice']\n",
    "\n",
    "    update.message.reply_text(\"Neat! Just so you know, this is what you already told me:\"\n",
    "                              \"{} You can tell me more, or change your opinion\"\n",
    "                              \" on something.\".format(facts_to_str(user_data)),\n",
    "                              reply_markup=markup)\n",
    "\n",
    "    return CHOOSING\n",
    "\n",
    "\n",
    "def done(update, context):\n",
    "    user_data = context.user_data\n",
    "    if 'choice' in user_data:\n",
    "        del user_data['choice']\n",
    "\n",
    "    update.message.reply_text(\"I learned these facts about you:\"\n",
    "                              \"{}\"\n",
    "                              \"Until next time!\".format(facts_to_str(user_data)))\n",
    "\n",
    "    user_data.clear()\n",
    "    return ConversationHandler.END\n",
    "\n",
    "\n",
    "def error(update, context):\n",
    "    \"\"\"Log Errors caused by Updates.\"\"\"\n",
    "    logger.warning('Update \"%s\" caused error \"%s\"', update, context.error)\n",
    "\n",
    "\n",
    "def main():\n",
    "    # Create the Updater and pass it your bot's token.\n",
    "    # Make sure to set use_context=True to use the new context based callbacks\n",
    "    # Post version 12 this will no longer be necessary\n",
    "    updater = Updater(\"984001690:AAHvJPz7H064B0J9CTJE-243qYMSOVhisPs\", use_context=True)\n",
    "\n",
    "    # Get the dispatcher to register handlers\n",
    "    dp = updater.dispatcher\n",
    "\n",
    "    # Add conversation handler with the states CHOOSING, TYPING_CHOICE and TYPING_REPLY\n",
    "    conv_handler = ConversationHandler(\n",
    "        entry_points=[CommandHandler('start', start)],\n",
    "\n",
    "        states={\n",
    "            CHOOSING: [MessageHandler(Filters.regex('^(Age|Favourite colour|Number of siblings)$'),\n",
    "                                      regular_choice),\n",
    "                       MessageHandler(Filters.regex('^Something else...$'),\n",
    "                                      custom_choice)\n",
    "                       ],\n",
    "\n",
    "            TYPING_CHOICE: [MessageHandler(Filters.text,\n",
    "                                           regular_choice)\n",
    "                            ],\n",
    "\n",
    "            TYPING_REPLY: [MessageHandler(Filters.text,\n",
    "                                          received_information),\n",
    "                           ],\n",
    "        },\n",
    "\n",
    "        fallbacks=[MessageHandler(Filters.regex('^Done$'), done)]\n",
    "    )\n",
    "\n",
    "    dp.add_handler(conv_handler)\n",
    "\n",
    "    # log all errors\n",
    "    dp.add_error_handler(error)\n",
    "\n",
    "    # Start the Bot\n",
    "    updater.start_polling()\n",
    "\n",
    "    # Run the bot until you press Ctrl-C or the process receives SIGINT,\n",
    "    # SIGTERM or SIGABRT. This should be used most of the time, since\n",
    "    # start_polling() is non-blocking and will stop the bot gracefully.\n",
    "    updater.idle()\n",
    "\n",
    "\n",
    "if __name__ == '__main__':\n",
    "    main()"
   ]
  },
  {
   "cell_type": "code",
   "execution_count": null,
   "metadata": {},
   "outputs": [
    {
     "name": "stderr",
     "output_type": "stream",
     "text": [
      "2019-12-05 22:52:32,858 - telegram.vendor.ptb_urllib3.urllib3.connectionpool - WARNING - Retrying (Retry(total=2, connect=None, read=None, redirect=None)) after connection broken by 'ConnectTimeoutError(<telegram.vendor.ptb_urllib3.urllib3.connection.VerifiedHTTPSConnection object at 0x0000016555C50A48>, 'Connection to api.telegram.org timed out. (connect timeout=5.0)')': /bot984001690:AAHvJPz7H064B0J9CTJE-243qYMSOVhisPs/getUpdates\n",
      "2019-12-05 22:52:37,876 - telegram.vendor.ptb_urllib3.urllib3.connectionpool - WARNING - Retrying (Retry(total=1, connect=None, read=None, redirect=None)) after connection broken by 'ConnectTimeoutError(<telegram.vendor.ptb_urllib3.urllib3.connection.VerifiedHTTPSConnection object at 0x0000016555AEEF88>, 'Connection to api.telegram.org timed out. (connect timeout=5.0)')': /bot984001690:AAHvJPz7H064B0J9CTJE-243qYMSOVhisPs/getUpdates\n",
      "2019-12-05 22:52:42,877 - telegram.vendor.ptb_urllib3.urllib3.connectionpool - WARNING - Retrying (Retry(total=0, connect=None, read=None, redirect=None)) after connection broken by 'ConnectTimeoutError(<telegram.vendor.ptb_urllib3.urllib3.connection.VerifiedHTTPSConnection object at 0x0000016556007108>, 'Connection to api.telegram.org timed out. (connect timeout=5.0)')': /bot984001690:AAHvJPz7H064B0J9CTJE-243qYMSOVhisPs/getUpdates\n",
      "2019-12-05 22:52:47,879 - telegram.ext.updater - ERROR - Error while getting Updates: urllib3 HTTPError HTTPSConnectionPool(host='api.telegram.org', port=443): Max retries exceeded with url: /bot984001690:AAHvJPz7H064B0J9CTJE-243qYMSOVhisPs/getUpdates (Caused by ConnectTimeoutError(<telegram.vendor.ptb_urllib3.urllib3.connection.VerifiedHTTPSConnection object at 0x0000016555AEE888>, 'Connection to api.telegram.org timed out. (connect timeout=5.0)'))\n",
      "2019-12-05 22:52:47,879 - __main__ - WARNING - Update \"None\" caused error \"urllib3 HTTPError HTTPSConnectionPool(host='api.telegram.org', port=443): Max retries exceeded with url: /bot984001690:AAHvJPz7H064B0J9CTJE-243qYMSOVhisPs/getUpdates (Caused by ConnectTimeoutError(<telegram.vendor.ptb_urllib3.urllib3.connection.VerifiedHTTPSConnection object at 0x0000016555AEE888>, 'Connection to api.telegram.org timed out. (connect timeout=5.0)'))\"\n",
      "2019-12-05 22:52:53,893 - telegram.vendor.ptb_urllib3.urllib3.connectionpool - WARNING - Retrying (Retry(total=2, connect=None, read=None, redirect=None)) after connection broken by 'ConnectTimeoutError(<telegram.vendor.ptb_urllib3.urllib3.connection.VerifiedHTTPSConnection object at 0x0000016555C50908>, 'Connection to api.telegram.org timed out. (connect timeout=5.0)')': /bot984001690:AAHvJPz7H064B0J9CTJE-243qYMSOVhisPs/getUpdates\n",
      "2019-12-05 22:52:58,905 - telegram.vendor.ptb_urllib3.urllib3.connectionpool - WARNING - Retrying (Retry(total=1, connect=None, read=None, redirect=None)) after connection broken by 'ConnectTimeoutError(<telegram.vendor.ptb_urllib3.urllib3.connection.VerifiedHTTPSConnection object at 0x000001655620FEC8>, 'Connection to api.telegram.org timed out. (connect timeout=5.0)')': /bot984001690:AAHvJPz7H064B0J9CTJE-243qYMSOVhisPs/getUpdates\n",
      "2019-12-05 22:53:03,906 - telegram.vendor.ptb_urllib3.urllib3.connectionpool - WARNING - Retrying (Retry(total=0, connect=None, read=None, redirect=None)) after connection broken by 'ConnectTimeoutError(<telegram.vendor.ptb_urllib3.urllib3.connection.VerifiedHTTPSConnection object at 0x000001655620F188>, 'Connection to api.telegram.org timed out. (connect timeout=5.0)')': /bot984001690:AAHvJPz7H064B0J9CTJE-243qYMSOVhisPs/getUpdates\n",
      "2019-12-05 22:53:08,914 - telegram.ext.updater - ERROR - Error while getting Updates: urllib3 HTTPError HTTPSConnectionPool(host='api.telegram.org', port=443): Max retries exceeded with url: /bot984001690:AAHvJPz7H064B0J9CTJE-243qYMSOVhisPs/getUpdates (Caused by ConnectTimeoutError(<telegram.vendor.ptb_urllib3.urllib3.connection.VerifiedHTTPSConnection object at 0x000001655620FB08>, 'Connection to api.telegram.org timed out. (connect timeout=5.0)'))\n",
      "2019-12-05 22:53:08,914 - __main__ - WARNING - Update \"None\" caused error \"urllib3 HTTPError HTTPSConnectionPool(host='api.telegram.org', port=443): Max retries exceeded with url: /bot984001690:AAHvJPz7H064B0J9CTJE-243qYMSOVhisPs/getUpdates (Caused by ConnectTimeoutError(<telegram.vendor.ptb_urllib3.urllib3.connection.VerifiedHTTPSConnection object at 0x000001655620FB08>, 'Connection to api.telegram.org timed out. (connect timeout=5.0)'))\"\n",
      "2019-12-08 09:05:46,544 - telegram.vendor.ptb_urllib3.urllib3.connectionpool - WARNING - Retrying (Retry(total=2, connect=None, read=None, redirect=None)) after connection broken by 'ConnectTimeoutError(<telegram.vendor.ptb_urllib3.urllib3.connection.VerifiedHTTPSConnection object at 0x0000016555E73608>, 'Connection to api.telegram.org timed out. (connect timeout=5.0)')': /bot984001690:AAHvJPz7H064B0J9CTJE-243qYMSOVhisPs/getUpdates\n",
      "2019-12-08 09:05:51,546 - telegram.vendor.ptb_urllib3.urllib3.connectionpool - WARNING - Retrying (Retry(total=1, connect=None, read=None, redirect=None)) after connection broken by 'ConnectTimeoutError(<telegram.vendor.ptb_urllib3.urllib3.connection.VerifiedHTTPSConnection object at 0x0000016555E73148>, 'Connection to api.telegram.org timed out. (connect timeout=5.0)')': /bot984001690:AAHvJPz7H064B0J9CTJE-243qYMSOVhisPs/getUpdates\n",
      "2019-12-08 09:05:56,553 - telegram.vendor.ptb_urllib3.urllib3.connectionpool - WARNING - Retrying (Retry(total=0, connect=None, read=None, redirect=None)) after connection broken by 'ConnectTimeoutError(<telegram.vendor.ptb_urllib3.urllib3.connection.VerifiedHTTPSConnection object at 0x0000016555A44908>, 'Connection to api.telegram.org timed out. (connect timeout=5.0)')': /bot984001690:AAHvJPz7H064B0J9CTJE-243qYMSOVhisPs/getUpdates\n",
      "2019-12-08 09:06:01,560 - telegram.ext.updater - ERROR - Error while getting Updates: urllib3 HTTPError HTTPSConnectionPool(host='api.telegram.org', port=443): Max retries exceeded with url: /bot984001690:AAHvJPz7H064B0J9CTJE-243qYMSOVhisPs/getUpdates (Caused by ConnectTimeoutError(<telegram.vendor.ptb_urllib3.urllib3.connection.VerifiedHTTPSConnection object at 0x0000016555B4E948>, 'Connection to api.telegram.org timed out. (connect timeout=5.0)'))\n",
      "2019-12-08 09:06:01,560 - __main__ - WARNING - Update \"None\" caused error \"urllib3 HTTPError HTTPSConnectionPool(host='api.telegram.org', port=443): Max retries exceeded with url: /bot984001690:AAHvJPz7H064B0J9CTJE-243qYMSOVhisPs/getUpdates (Caused by ConnectTimeoutError(<telegram.vendor.ptb_urllib3.urllib3.connection.VerifiedHTTPSConnection object at 0x0000016555B4E948>, 'Connection to api.telegram.org timed out. (connect timeout=5.0)'))\"\n",
      "2019-12-08 09:06:07,578 - telegram.vendor.ptb_urllib3.urllib3.connectionpool - WARNING - Retrying (Retry(total=2, connect=None, read=None, redirect=None)) after connection broken by 'ConnectTimeoutError(<telegram.vendor.ptb_urllib3.urllib3.connection.VerifiedHTTPSConnection object at 0x0000016555D98E88>, 'Connection to api.telegram.org timed out. (connect timeout=5.0)')': /bot984001690:AAHvJPz7H064B0J9CTJE-243qYMSOVhisPs/getUpdates\n",
      "2019-12-08 09:06:12,585 - telegram.vendor.ptb_urllib3.urllib3.connectionpool - WARNING - Retrying (Retry(total=1, connect=None, read=None, redirect=None)) after connection broken by 'ConnectTimeoutError(<telegram.vendor.ptb_urllib3.urllib3.connection.VerifiedHTTPSConnection object at 0x000001655480CEC8>, 'Connection to api.telegram.org timed out. (connect timeout=5.0)')': /bot984001690:AAHvJPz7H064B0J9CTJE-243qYMSOVhisPs/getUpdates\n",
      "2019-12-08 09:06:17,592 - telegram.vendor.ptb_urllib3.urllib3.connectionpool - WARNING - Retrying (Retry(total=0, connect=None, read=None, redirect=None)) after connection broken by 'ConnectTimeoutError(<telegram.vendor.ptb_urllib3.urllib3.connection.VerifiedHTTPSConnection object at 0x0000016555AEE308>, 'Connection to api.telegram.org timed out. (connect timeout=5.0)')': /bot984001690:AAHvJPz7H064B0J9CTJE-243qYMSOVhisPs/getUpdates\n",
      "2019-12-08 09:06:22,604 - telegram.ext.updater - ERROR - Error while getting Updates: urllib3 HTTPError HTTPSConnectionPool(host='api.telegram.org', port=443): Max retries exceeded with url: /bot984001690:AAHvJPz7H064B0J9CTJE-243qYMSOVhisPs/getUpdates (Caused by ConnectTimeoutError(<telegram.vendor.ptb_urllib3.urllib3.connection.VerifiedHTTPSConnection object at 0x0000016555AEEB48>, 'Connection to api.telegram.org timed out. (connect timeout=5.0)'))\n"
     ]
    },
    {
     "name": "stderr",
     "output_type": "stream",
     "text": [
      "2019-12-08 09:06:22,604 - __main__ - WARNING - Update \"None\" caused error \"urllib3 HTTPError HTTPSConnectionPool(host='api.telegram.org', port=443): Max retries exceeded with url: /bot984001690:AAHvJPz7H064B0J9CTJE-243qYMSOVhisPs/getUpdates (Caused by ConnectTimeoutError(<telegram.vendor.ptb_urllib3.urllib3.connection.VerifiedHTTPSConnection object at 0x0000016555AEEB48>, 'Connection to api.telegram.org timed out. (connect timeout=5.0)'))\"\n",
      "2019-12-08 09:06:29,111 - telegram.vendor.ptb_urllib3.urllib3.connectionpool - WARNING - Retrying (Retry(total=2, connect=None, read=None, redirect=None)) after connection broken by 'ConnectTimeoutError(<telegram.vendor.ptb_urllib3.urllib3.connection.VerifiedHTTPSConnection object at 0x0000016555D98CC8>, 'Connection to api.telegram.org timed out. (connect timeout=5.0)')': /bot984001690:AAHvJPz7H064B0J9CTJE-243qYMSOVhisPs/getUpdates\n",
      "2019-12-08 09:06:34,123 - telegram.vendor.ptb_urllib3.urllib3.connectionpool - WARNING - Retrying (Retry(total=1, connect=None, read=None, redirect=None)) after connection broken by 'ConnectTimeoutError(<telegram.vendor.ptb_urllib3.urllib3.connection.VerifiedHTTPSConnection object at 0x0000016555B4E188>, 'Connection to api.telegram.org timed out. (connect timeout=5.0)')': /bot984001690:AAHvJPz7H064B0J9CTJE-243qYMSOVhisPs/getUpdates\n",
      "2019-12-08 09:06:39,130 - telegram.vendor.ptb_urllib3.urllib3.connectionpool - WARNING - Retrying (Retry(total=0, connect=None, read=None, redirect=None)) after connection broken by 'ConnectTimeoutError(<telegram.vendor.ptb_urllib3.urllib3.connection.VerifiedHTTPSConnection object at 0x000001655620FD08>, 'Connection to api.telegram.org timed out. (connect timeout=5.0)')': /bot984001690:AAHvJPz7H064B0J9CTJE-243qYMSOVhisPs/getUpdates\n",
      "2019-12-08 09:06:44,137 - telegram.ext.updater - ERROR - Error while getting Updates: urllib3 HTTPError HTTPSConnectionPool(host='api.telegram.org', port=443): Max retries exceeded with url: /bot984001690:AAHvJPz7H064B0J9CTJE-243qYMSOVhisPs/getUpdates (Caused by ConnectTimeoutError(<telegram.vendor.ptb_urllib3.urllib3.connection.VerifiedHTTPSConnection object at 0x00000165560070C8>, 'Connection to api.telegram.org timed out. (connect timeout=5.0)'))\n",
      "2019-12-08 09:06:44,137 - __main__ - WARNING - Update \"None\" caused error \"urllib3 HTTPError HTTPSConnectionPool(host='api.telegram.org', port=443): Max retries exceeded with url: /bot984001690:AAHvJPz7H064B0J9CTJE-243qYMSOVhisPs/getUpdates (Caused by ConnectTimeoutError(<telegram.vendor.ptb_urllib3.urllib3.connection.VerifiedHTTPSConnection object at 0x00000165560070C8>, 'Connection to api.telegram.org timed out. (connect timeout=5.0)'))\"\n",
      "2019-12-08 09:06:51,393 - telegram.vendor.ptb_urllib3.urllib3.connectionpool - WARNING - Retrying (Retry(total=2, connect=None, read=None, redirect=None)) after connection broken by 'ConnectTimeoutError(<telegram.vendor.ptb_urllib3.urllib3.connection.VerifiedHTTPSConnection object at 0x0000016555AEE8C8>, 'Connection to api.telegram.org timed out. (connect timeout=5.0)')': /bot984001690:AAHvJPz7H064B0J9CTJE-243qYMSOVhisPs/getUpdates\n",
      "2019-12-08 09:06:56,400 - telegram.vendor.ptb_urllib3.urllib3.connectionpool - WARNING - Retrying (Retry(total=1, connect=None, read=None, redirect=None)) after connection broken by 'ConnectTimeoutError(<telegram.vendor.ptb_urllib3.urllib3.connection.VerifiedHTTPSConnection object at 0x0000016555B4EB08>, 'Connection to api.telegram.org timed out. (connect timeout=5.0)')': /bot984001690:AAHvJPz7H064B0J9CTJE-243qYMSOVhisPs/getUpdates\n",
      "2019-12-08 09:07:01,412 - telegram.vendor.ptb_urllib3.urllib3.connectionpool - WARNING - Retrying (Retry(total=0, connect=None, read=None, redirect=None)) after connection broken by 'ConnectTimeoutError(<telegram.vendor.ptb_urllib3.urllib3.connection.VerifiedHTTPSConnection object at 0x0000016555C50988>, 'Connection to api.telegram.org timed out. (connect timeout=5.0)')': /bot984001690:AAHvJPz7H064B0J9CTJE-243qYMSOVhisPs/getUpdates\n",
      "2019-12-08 09:07:06,419 - telegram.ext.updater - ERROR - Error while getting Updates: urllib3 HTTPError HTTPSConnectionPool(host='api.telegram.org', port=443): Max retries exceeded with url: /bot984001690:AAHvJPz7H064B0J9CTJE-243qYMSOVhisPs/getUpdates (Caused by ConnectTimeoutError(<telegram.vendor.ptb_urllib3.urllib3.connection.VerifiedHTTPSConnection object at 0x000001655609C3C8>, 'Connection to api.telegram.org timed out. (connect timeout=5.0)'))\n",
      "2019-12-08 09:07:06,419 - __main__ - WARNING - Update \"None\" caused error \"urllib3 HTTPError HTTPSConnectionPool(host='api.telegram.org', port=443): Max retries exceeded with url: /bot984001690:AAHvJPz7H064B0J9CTJE-243qYMSOVhisPs/getUpdates (Caused by ConnectTimeoutError(<telegram.vendor.ptb_urllib3.urllib3.connection.VerifiedHTTPSConnection object at 0x000001655609C3C8>, 'Connection to api.telegram.org timed out. (connect timeout=5.0)'))\"\n",
      "2019-12-08 09:07:14,807 - telegram.vendor.ptb_urllib3.urllib3.connectionpool - WARNING - Retrying (Retry(total=2, connect=None, read=None, redirect=None)) after connection broken by 'ConnectTimeoutError(<telegram.vendor.ptb_urllib3.urllib3.connection.VerifiedHTTPSConnection object at 0x0000016555AEE588>, 'Connection to api.telegram.org timed out. (connect timeout=5.0)')': /bot984001690:AAHvJPz7H064B0J9CTJE-243qYMSOVhisPs/getUpdates\n",
      "2019-12-08 09:07:19,810 - telegram.vendor.ptb_urllib3.urllib3.connectionpool - WARNING - Retrying (Retry(total=1, connect=None, read=None, redirect=None)) after connection broken by 'ConnectTimeoutError(<telegram.vendor.ptb_urllib3.urllib3.connection.VerifiedHTTPSConnection object at 0x0000016555EB3808>, 'Connection to api.telegram.org timed out. (connect timeout=5.0)')': /bot984001690:AAHvJPz7H064B0J9CTJE-243qYMSOVhisPs/getUpdates\n",
      "2019-12-08 09:07:24,822 - telegram.vendor.ptb_urllib3.urllib3.connectionpool - WARNING - Retrying (Retry(total=0, connect=None, read=None, redirect=None)) after connection broken by 'ConnectTimeoutError(<telegram.vendor.ptb_urllib3.urllib3.connection.VerifiedHTTPSConnection object at 0x0000016556040B48>, 'Connection to api.telegram.org timed out. (connect timeout=5.0)')': /bot984001690:AAHvJPz7H064B0J9CTJE-243qYMSOVhisPs/getUpdates\n",
      "2019-12-08 09:07:29,829 - telegram.ext.updater - ERROR - Error while getting Updates: urllib3 HTTPError HTTPSConnectionPool(host='api.telegram.org', port=443): Max retries exceeded with url: /bot984001690:AAHvJPz7H064B0J9CTJE-243qYMSOVhisPs/getUpdates (Caused by ConnectTimeoutError(<telegram.vendor.ptb_urllib3.urllib3.connection.VerifiedHTTPSConnection object at 0x0000016556040A88>, 'Connection to api.telegram.org timed out. (connect timeout=5.0)'))\n",
      "2019-12-08 09:07:29,829 - __main__ - WARNING - Update \"None\" caused error \"urllib3 HTTPError HTTPSConnectionPool(host='api.telegram.org', port=443): Max retries exceeded with url: /bot984001690:AAHvJPz7H064B0J9CTJE-243qYMSOVhisPs/getUpdates (Caused by ConnectTimeoutError(<telegram.vendor.ptb_urllib3.urllib3.connection.VerifiedHTTPSConnection object at 0x0000016556040A88>, 'Connection to api.telegram.org timed out. (connect timeout=5.0)'))\"\n",
      "2019-12-08 09:07:39,921 - telegram.vendor.ptb_urllib3.urllib3.connectionpool - WARNING - Retrying (Retry(total=2, connect=None, read=None, redirect=None)) after connection broken by 'ConnectTimeoutError(<telegram.vendor.ptb_urllib3.urllib3.connection.VerifiedHTTPSConnection object at 0x000001655609CD88>, 'Connection to api.telegram.org timed out. (connect timeout=5.0)')': /bot984001690:AAHvJPz7H064B0J9CTJE-243qYMSOVhisPs/getUpdates\n",
      "2019-12-08 09:07:44,923 - telegram.vendor.ptb_urllib3.urllib3.connectionpool - WARNING - Retrying (Retry(total=1, connect=None, read=None, redirect=None)) after connection broken by 'ConnectTimeoutError(<telegram.vendor.ptb_urllib3.urllib3.connection.VerifiedHTTPSConnection object at 0x000001655626AE88>, 'Connection to api.telegram.org timed out. (connect timeout=5.0)')': /bot984001690:AAHvJPz7H064B0J9CTJE-243qYMSOVhisPs/getUpdates\n",
      "2019-12-08 09:07:49,935 - telegram.vendor.ptb_urllib3.urllib3.connectionpool - WARNING - Retrying (Retry(total=0, connect=None, read=None, redirect=None)) after connection broken by 'ConnectTimeoutError(<telegram.vendor.ptb_urllib3.urllib3.connection.VerifiedHTTPSConnection object at 0x000001655609C888>, 'Connection to api.telegram.org timed out. (connect timeout=5.0)')': /bot984001690:AAHvJPz7H064B0J9CTJE-243qYMSOVhisPs/getUpdates\n"
     ]
    },
    {
     "name": "stderr",
     "output_type": "stream",
     "text": [
      "2019-12-08 09:07:54,937 - telegram.ext.updater - ERROR - Error while getting Updates: urllib3 HTTPError HTTPSConnectionPool(host='api.telegram.org', port=443): Max retries exceeded with url: /bot984001690:AAHvJPz7H064B0J9CTJE-243qYMSOVhisPs/getUpdates (Caused by ConnectTimeoutError(<telegram.vendor.ptb_urllib3.urllib3.connection.VerifiedHTTPSConnection object at 0x0000016555AA13C8>, 'Connection to api.telegram.org timed out. (connect timeout=5.0)'))\n",
      "2019-12-08 09:07:54,937 - __main__ - WARNING - Update \"None\" caused error \"urllib3 HTTPError HTTPSConnectionPool(host='api.telegram.org', port=443): Max retries exceeded with url: /bot984001690:AAHvJPz7H064B0J9CTJE-243qYMSOVhisPs/getUpdates (Caused by ConnectTimeoutError(<telegram.vendor.ptb_urllib3.urllib3.connection.VerifiedHTTPSConnection object at 0x0000016555AA13C8>, 'Connection to api.telegram.org timed out. (connect timeout=5.0)'))\"\n",
      "2019-12-08 09:08:07,546 - telegram.vendor.ptb_urllib3.urllib3.connectionpool - WARNING - Retrying (Retry(total=2, connect=None, read=None, redirect=None)) after connection broken by 'ConnectTimeoutError(<telegram.vendor.ptb_urllib3.urllib3.connection.VerifiedHTTPSConnection object at 0x00000165560406C8>, 'Connection to api.telegram.org timed out. (connect timeout=5.0)')': /bot984001690:AAHvJPz7H064B0J9CTJE-243qYMSOVhisPs/getUpdates\n",
      "2019-12-08 09:08:12,553 - telegram.vendor.ptb_urllib3.urllib3.connectionpool - WARNING - Retrying (Retry(total=1, connect=None, read=None, redirect=None)) after connection broken by 'ConnectTimeoutError(<telegram.vendor.ptb_urllib3.urllib3.connection.VerifiedHTTPSConnection object at 0x000001655609C8C8>, 'Connection to api.telegram.org timed out. (connect timeout=5.0)')': /bot984001690:AAHvJPz7H064B0J9CTJE-243qYMSOVhisPs/getUpdates\n",
      "2019-12-08 09:08:17,565 - telegram.vendor.ptb_urllib3.urllib3.connectionpool - WARNING - Retrying (Retry(total=0, connect=None, read=None, redirect=None)) after connection broken by 'ConnectTimeoutError(<telegram.vendor.ptb_urllib3.urllib3.connection.VerifiedHTTPSConnection object at 0x000001655609C348>, 'Connection to api.telegram.org timed out. (connect timeout=5.0)')': /bot984001690:AAHvJPz7H064B0J9CTJE-243qYMSOVhisPs/getUpdates\n",
      "2019-12-08 09:08:22,572 - telegram.ext.updater - ERROR - Error while getting Updates: urllib3 HTTPError HTTPSConnectionPool(host='api.telegram.org', port=443): Max retries exceeded with url: /bot984001690:AAHvJPz7H064B0J9CTJE-243qYMSOVhisPs/getUpdates (Caused by ConnectTimeoutError(<telegram.vendor.ptb_urllib3.urllib3.connection.VerifiedHTTPSConnection object at 0x000001655609CE08>, 'Connection to api.telegram.org timed out. (connect timeout=5.0)'))\n",
      "2019-12-08 09:08:22,572 - __main__ - WARNING - Update \"None\" caused error \"urllib3 HTTPError HTTPSConnectionPool(host='api.telegram.org', port=443): Max retries exceeded with url: /bot984001690:AAHvJPz7H064B0J9CTJE-243qYMSOVhisPs/getUpdates (Caused by ConnectTimeoutError(<telegram.vendor.ptb_urllib3.urllib3.connection.VerifiedHTTPSConnection object at 0x000001655609CE08>, 'Connection to api.telegram.org timed out. (connect timeout=5.0)'))\"\n",
      "2019-12-08 09:08:38,967 - telegram.vendor.ptb_urllib3.urllib3.connectionpool - WARNING - Retrying (Retry(total=2, connect=None, read=None, redirect=None)) after connection broken by 'ConnectTimeoutError(<telegram.vendor.ptb_urllib3.urllib3.connection.VerifiedHTTPSConnection object at 0x0000016556040C08>, 'Connection to api.telegram.org timed out. (connect timeout=5.0)')': /bot984001690:AAHvJPz7H064B0J9CTJE-243qYMSOVhisPs/getUpdates\n",
      "2019-12-08 09:08:43,967 - telegram.vendor.ptb_urllib3.urllib3.connectionpool - WARNING - Retrying (Retry(total=1, connect=None, read=None, redirect=None)) after connection broken by 'ConnectTimeoutError(<telegram.vendor.ptb_urllib3.urllib3.connection.VerifiedHTTPSConnection object at 0x0000016556007E48>, 'Connection to api.telegram.org timed out. (connect timeout=5.0)')': /bot984001690:AAHvJPz7H064B0J9CTJE-243qYMSOVhisPs/getUpdates\n",
      "2019-12-08 09:08:48,970 - telegram.vendor.ptb_urllib3.urllib3.connectionpool - WARNING - Retrying (Retry(total=0, connect=None, read=None, redirect=None)) after connection broken by 'ConnectTimeoutError(<telegram.vendor.ptb_urllib3.urllib3.connection.VerifiedHTTPSConnection object at 0x000001655480CEC8>, 'Connection to api.telegram.org timed out. (connect timeout=5.0)')': /bot984001690:AAHvJPz7H064B0J9CTJE-243qYMSOVhisPs/getUpdates\n",
      "2019-12-08 09:08:53,971 - telegram.ext.updater - ERROR - Error while getting Updates: urllib3 HTTPError HTTPSConnectionPool(host='api.telegram.org', port=443): Max retries exceeded with url: /bot984001690:AAHvJPz7H064B0J9CTJE-243qYMSOVhisPs/getUpdates (Caused by ConnectTimeoutError(<telegram.vendor.ptb_urllib3.urllib3.connection.VerifiedHTTPSConnection object at 0x0000016555AEE648>, 'Connection to api.telegram.org timed out. (connect timeout=5.0)'))\n",
      "2019-12-08 09:08:53,971 - __main__ - WARNING - Update \"None\" caused error \"urllib3 HTTPError HTTPSConnectionPool(host='api.telegram.org', port=443): Max retries exceeded with url: /bot984001690:AAHvJPz7H064B0J9CTJE-243qYMSOVhisPs/getUpdates (Caused by ConnectTimeoutError(<telegram.vendor.ptb_urllib3.urllib3.connection.VerifiedHTTPSConnection object at 0x0000016555AEE648>, 'Connection to api.telegram.org timed out. (connect timeout=5.0)'))\"\n",
      "2019-12-08 09:09:16,071 - telegram.vendor.ptb_urllib3.urllib3.connectionpool - WARNING - Retrying (Retry(total=2, connect=None, read=None, redirect=None)) after connection broken by 'ConnectTimeoutError(<telegram.vendor.ptb_urllib3.urllib3.connection.VerifiedHTTPSConnection object at 0x0000016555C50C08>, 'Connection to api.telegram.org timed out. (connect timeout=5.0)')': /bot984001690:AAHvJPz7H064B0J9CTJE-243qYMSOVhisPs/getUpdates\n",
      "2019-12-08 09:09:21,083 - telegram.vendor.ptb_urllib3.urllib3.connectionpool - WARNING - Retrying (Retry(total=1, connect=None, read=None, redirect=None)) after connection broken by 'ConnectTimeoutError(<telegram.vendor.ptb_urllib3.urllib3.connection.VerifiedHTTPSConnection object at 0x0000016556007608>, 'Connection to api.telegram.org timed out. (connect timeout=5.0)')': /bot984001690:AAHvJPz7H064B0J9CTJE-243qYMSOVhisPs/getUpdates\n",
      "2019-12-08 09:09:26,084 - telegram.vendor.ptb_urllib3.urllib3.connectionpool - WARNING - Retrying (Retry(total=0, connect=None, read=None, redirect=None)) after connection broken by 'ConnectTimeoutError(<telegram.vendor.ptb_urllib3.urllib3.connection.VerifiedHTTPSConnection object at 0x0000016555A6C348>, 'Connection to api.telegram.org timed out. (connect timeout=5.0)')': /bot984001690:AAHvJPz7H064B0J9CTJE-243qYMSOVhisPs/getUpdates\n",
      "2019-12-08 09:09:31,096 - telegram.ext.updater - ERROR - Error while getting Updates: urllib3 HTTPError HTTPSConnectionPool(host='api.telegram.org', port=443): Max retries exceeded with url: /bot984001690:AAHvJPz7H064B0J9CTJE-243qYMSOVhisPs/getUpdates (Caused by ConnectTimeoutError(<telegram.vendor.ptb_urllib3.urllib3.connection.VerifiedHTTPSConnection object at 0x0000016555B4EB08>, 'Connection to api.telegram.org timed out. (connect timeout=5.0)'))\n",
      "2019-12-08 09:09:31,096 - __main__ - WARNING - Update \"None\" caused error \"urllib3 HTTPError HTTPSConnectionPool(host='api.telegram.org', port=443): Max retries exceeded with url: /bot984001690:AAHvJPz7H064B0J9CTJE-243qYMSOVhisPs/getUpdates (Caused by ConnectTimeoutError(<telegram.vendor.ptb_urllib3.urllib3.connection.VerifiedHTTPSConnection object at 0x0000016555B4EB08>, 'Connection to api.telegram.org timed out. (connect timeout=5.0)'))\"\n",
      "2019-12-08 09:10:01,736 - telegram.vendor.ptb_urllib3.urllib3.connectionpool - WARNING - Retrying (Retry(total=2, connect=None, read=None, redirect=None)) after connection broken by 'ConnectTimeoutError(<telegram.vendor.ptb_urllib3.urllib3.connection.VerifiedHTTPSConnection object at 0x0000016555AEEC08>, 'Connection to api.telegram.org timed out. (connect timeout=5.0)')': /bot984001690:AAHvJPz7H064B0J9CTJE-243qYMSOVhisPs/getUpdates\n",
      "2019-12-08 09:10:06,748 - telegram.vendor.ptb_urllib3.urllib3.connectionpool - WARNING - Retrying (Retry(total=1, connect=None, read=None, redirect=None)) after connection broken by 'ConnectTimeoutError(<telegram.vendor.ptb_urllib3.urllib3.connection.VerifiedHTTPSConnection object at 0x0000016556007A88>, 'Connection to api.telegram.org timed out. (connect timeout=5.0)')': /bot984001690:AAHvJPz7H064B0J9CTJE-243qYMSOVhisPs/getUpdates\n"
     ]
    },
    {
     "name": "stderr",
     "output_type": "stream",
     "text": [
      "2019-12-08 09:10:11,771 - telegram.vendor.ptb_urllib3.urllib3.connectionpool - WARNING - Retrying (Retry(total=0, connect=None, read=None, redirect=None)) after connection broken by 'ConnectTimeoutError(<telegram.vendor.ptb_urllib3.urllib3.connection.VerifiedHTTPSConnection object at 0x000001655620F4C8>, 'Connection to api.telegram.org timed out. (connect timeout=5.0)')': /bot984001690:AAHvJPz7H064B0J9CTJE-243qYMSOVhisPs/getUpdates\n",
      "2019-12-08 09:10:16,783 - telegram.ext.updater - ERROR - Error while getting Updates: urllib3 HTTPError HTTPSConnectionPool(host='api.telegram.org', port=443): Max retries exceeded with url: /bot984001690:AAHvJPz7H064B0J9CTJE-243qYMSOVhisPs/getUpdates (Caused by ConnectTimeoutError(<telegram.vendor.ptb_urllib3.urllib3.connection.VerifiedHTTPSConnection object at 0x0000016555AA1248>, 'Connection to api.telegram.org timed out. (connect timeout=5.0)'))\n",
      "2019-12-08 09:10:16,783 - __main__ - WARNING - Update \"None\" caused error \"urllib3 HTTPError HTTPSConnectionPool(host='api.telegram.org', port=443): Max retries exceeded with url: /bot984001690:AAHvJPz7H064B0J9CTJE-243qYMSOVhisPs/getUpdates (Caused by ConnectTimeoutError(<telegram.vendor.ptb_urllib3.urllib3.connection.VerifiedHTTPSConnection object at 0x0000016555AA1248>, 'Connection to api.telegram.org timed out. (connect timeout=5.0)'))\"\n",
      "2019-12-08 09:11:00,236 - telegram.vendor.ptb_urllib3.urllib3.connectionpool - WARNING - Retrying (Retry(total=2, connect=None, read=None, redirect=None)) after connection broken by 'ConnectTimeoutError(<telegram.vendor.ptb_urllib3.urllib3.connection.VerifiedHTTPSConnection object at 0x0000016555B702C8>, 'Connection to api.telegram.org timed out. (connect timeout=5.0)')': /bot984001690:AAHvJPz7H064B0J9CTJE-243qYMSOVhisPs/getUpdates\n",
      "2019-12-08 09:11:05,237 - telegram.vendor.ptb_urllib3.urllib3.connectionpool - WARNING - Retrying (Retry(total=1, connect=None, read=None, redirect=None)) after connection broken by 'ConnectTimeoutError(<telegram.vendor.ptb_urllib3.urllib3.connection.VerifiedHTTPSConnection object at 0x0000016555D859C8>, 'Connection to api.telegram.org timed out. (connect timeout=5.0)')': /bot984001690:AAHvJPz7H064B0J9CTJE-243qYMSOVhisPs/getUpdates\n",
      "2019-12-08 09:11:10,250 - telegram.vendor.ptb_urllib3.urllib3.connectionpool - WARNING - Retrying (Retry(total=0, connect=None, read=None, redirect=None)) after connection broken by 'ConnectTimeoutError(<telegram.vendor.ptb_urllib3.urllib3.connection.VerifiedHTTPSConnection object at 0x0000016555D85648>, 'Connection to api.telegram.org timed out. (connect timeout=5.0)')': /bot984001690:AAHvJPz7H064B0J9CTJE-243qYMSOVhisPs/getUpdates\n",
      "2019-12-08 09:11:15,262 - telegram.ext.updater - ERROR - Error while getting Updates: urllib3 HTTPError HTTPSConnectionPool(host='api.telegram.org', port=443): Max retries exceeded with url: /bot984001690:AAHvJPz7H064B0J9CTJE-243qYMSOVhisPs/getUpdates (Caused by ConnectTimeoutError(<telegram.vendor.ptb_urllib3.urllib3.connection.VerifiedHTTPSConnection object at 0x0000016555A655C8>, 'Connection to api.telegram.org timed out. (connect timeout=5.0)'))\n",
      "2019-12-08 09:11:15,262 - __main__ - WARNING - Update \"None\" caused error \"urllib3 HTTPError HTTPSConnectionPool(host='api.telegram.org', port=443): Max retries exceeded with url: /bot984001690:AAHvJPz7H064B0J9CTJE-243qYMSOVhisPs/getUpdates (Caused by ConnectTimeoutError(<telegram.vendor.ptb_urllib3.urllib3.connection.VerifiedHTTPSConnection object at 0x0000016555A655C8>, 'Connection to api.telegram.org timed out. (connect timeout=5.0)'))\"\n",
      "2019-12-08 09:11:50,284 - telegram.vendor.ptb_urllib3.urllib3.connectionpool - WARNING - Retrying (Retry(total=2, connect=None, read=None, redirect=None)) after connection broken by 'ConnectTimeoutError(<telegram.vendor.ptb_urllib3.urllib3.connection.VerifiedHTTPSConnection object at 0x0000016555D85108>, 'Connection to api.telegram.org timed out. (connect timeout=5.0)')': /bot984001690:AAHvJPz7H064B0J9CTJE-243qYMSOVhisPs/getUpdates\n",
      "2019-12-08 09:11:55,296 - telegram.vendor.ptb_urllib3.urllib3.connectionpool - WARNING - Retrying (Retry(total=1, connect=None, read=None, redirect=None)) after connection broken by 'ConnectTimeoutError(<telegram.vendor.ptb_urllib3.urllib3.connection.VerifiedHTTPSConnection object at 0x0000016555D85048>, 'Connection to api.telegram.org timed out. (connect timeout=5.0)')': /bot984001690:AAHvJPz7H064B0J9CTJE-243qYMSOVhisPs/getUpdates\n",
      "2019-12-08 09:12:00,309 - telegram.vendor.ptb_urllib3.urllib3.connectionpool - WARNING - Retrying (Retry(total=0, connect=None, read=None, redirect=None)) after connection broken by 'ConnectTimeoutError(<telegram.vendor.ptb_urllib3.urllib3.connection.VerifiedHTTPSConnection object at 0x0000016555EF0CC8>, 'Connection to api.telegram.org timed out. (connect timeout=5.0)')': /bot984001690:AAHvJPz7H064B0J9CTJE-243qYMSOVhisPs/getUpdates\n",
      "2019-12-08 09:12:05,316 - telegram.ext.updater - ERROR - Error while getting Updates: urllib3 HTTPError HTTPSConnectionPool(host='api.telegram.org', port=443): Max retries exceeded with url: /bot984001690:AAHvJPz7H064B0J9CTJE-243qYMSOVhisPs/getUpdates (Caused by ConnectTimeoutError(<telegram.vendor.ptb_urllib3.urllib3.connection.VerifiedHTTPSConnection object at 0x0000016555EF0788>, 'Connection to api.telegram.org timed out. (connect timeout=5.0)'))\n",
      "2019-12-08 09:12:05,316 - __main__ - WARNING - Update \"None\" caused error \"urllib3 HTTPError HTTPSConnectionPool(host='api.telegram.org', port=443): Max retries exceeded with url: /bot984001690:AAHvJPz7H064B0J9CTJE-243qYMSOVhisPs/getUpdates (Caused by ConnectTimeoutError(<telegram.vendor.ptb_urllib3.urllib3.connection.VerifiedHTTPSConnection object at 0x0000016555EF0788>, 'Connection to api.telegram.org timed out. (connect timeout=5.0)'))\"\n",
      "2019-12-08 09:12:40,328 - telegram.vendor.ptb_urllib3.urllib3.connectionpool - WARNING - Retrying (Retry(total=2, connect=None, read=None, redirect=None)) after connection broken by 'ConnectTimeoutError(<telegram.vendor.ptb_urllib3.urllib3.connection.VerifiedHTTPSConnection object at 0x0000016555A65888>, 'Connection to api.telegram.org timed out. (connect timeout=5.0)')': /bot984001690:AAHvJPz7H064B0J9CTJE-243qYMSOVhisPs/getUpdates\n",
      "2019-12-08 09:12:45,340 - telegram.vendor.ptb_urllib3.urllib3.connectionpool - WARNING - Retrying (Retry(total=1, connect=None, read=None, redirect=None)) after connection broken by 'ConnectTimeoutError(<telegram.vendor.ptb_urllib3.urllib3.connection.VerifiedHTTPSConnection object at 0x0000016555A44908>, 'Connection to api.telegram.org timed out. (connect timeout=5.0)')': /bot984001690:AAHvJPz7H064B0J9CTJE-243qYMSOVhisPs/getUpdates\n",
      "2019-12-08 09:12:50,347 - telegram.vendor.ptb_urllib3.urllib3.connectionpool - WARNING - Retrying (Retry(total=0, connect=None, read=None, redirect=None)) after connection broken by 'ConnectTimeoutError(<telegram.vendor.ptb_urllib3.urllib3.connection.VerifiedHTTPSConnection object at 0x0000016555A65CC8>, 'Connection to api.telegram.org timed out. (connect timeout=5.0)')': /bot984001690:AAHvJPz7H064B0J9CTJE-243qYMSOVhisPs/getUpdates\n",
      "2019-12-08 09:12:55,354 - telegram.ext.updater - ERROR - Error while getting Updates: urllib3 HTTPError HTTPSConnectionPool(host='api.telegram.org', port=443): Max retries exceeded with url: /bot984001690:AAHvJPz7H064B0J9CTJE-243qYMSOVhisPs/getUpdates (Caused by ConnectTimeoutError(<telegram.vendor.ptb_urllib3.urllib3.connection.VerifiedHTTPSConnection object at 0x0000016555E73E48>, 'Connection to api.telegram.org timed out. (connect timeout=5.0)'))\n",
      "2019-12-08 09:12:55,354 - __main__ - WARNING - Update \"None\" caused error \"urllib3 HTTPError HTTPSConnectionPool(host='api.telegram.org', port=443): Max retries exceeded with url: /bot984001690:AAHvJPz7H064B0J9CTJE-243qYMSOVhisPs/getUpdates (Caused by ConnectTimeoutError(<telegram.vendor.ptb_urllib3.urllib3.connection.VerifiedHTTPSConnection object at 0x0000016555E73E48>, 'Connection to api.telegram.org timed out. (connect timeout=5.0)'))\"\n",
      "2019-12-08 09:13:30,392 - telegram.vendor.ptb_urllib3.urllib3.connectionpool - WARNING - Retrying (Retry(total=2, connect=None, read=None, redirect=None)) after connection broken by 'ConnectTimeoutError(<telegram.vendor.ptb_urllib3.urllib3.connection.VerifiedHTTPSConnection object at 0x0000016555D85188>, 'Connection to api.telegram.org timed out. (connect timeout=5.0)')': /bot984001690:AAHvJPz7H064B0J9CTJE-243qYMSOVhisPs/getUpdates\n"
     ]
    },
    {
     "name": "stderr",
     "output_type": "stream",
     "text": [
      "2019-12-08 09:13:35,399 - telegram.vendor.ptb_urllib3.urllib3.connectionpool - WARNING - Retrying (Retry(total=1, connect=None, read=None, redirect=None)) after connection broken by 'ConnectTimeoutError(<telegram.vendor.ptb_urllib3.urllib3.connection.VerifiedHTTPSConnection object at 0x0000016555AEEEC8>, 'Connection to api.telegram.org timed out. (connect timeout=5.0)')': /bot984001690:AAHvJPz7H064B0J9CTJE-243qYMSOVhisPs/getUpdates\n",
      "2019-12-08 09:13:40,411 - telegram.vendor.ptb_urllib3.urllib3.connectionpool - WARNING - Retrying (Retry(total=0, connect=None, read=None, redirect=None)) after connection broken by 'ConnectTimeoutError(<telegram.vendor.ptb_urllib3.urllib3.connection.VerifiedHTTPSConnection object at 0x0000016555AEEB08>, 'Connection to api.telegram.org timed out. (connect timeout=5.0)')': /bot984001690:AAHvJPz7H064B0J9CTJE-243qYMSOVhisPs/getUpdates\n",
      "2019-12-08 09:13:45,423 - telegram.ext.updater - ERROR - Error while getting Updates: urllib3 HTTPError HTTPSConnectionPool(host='api.telegram.org', port=443): Max retries exceeded with url: /bot984001690:AAHvJPz7H064B0J9CTJE-243qYMSOVhisPs/getUpdates (Caused by ConnectTimeoutError(<telegram.vendor.ptb_urllib3.urllib3.connection.VerifiedHTTPSConnection object at 0x0000016555AEE048>, 'Connection to api.telegram.org timed out. (connect timeout=5.0)'))\n",
      "2019-12-08 09:13:45,423 - __main__ - WARNING - Update \"None\" caused error \"urllib3 HTTPError HTTPSConnectionPool(host='api.telegram.org', port=443): Max retries exceeded with url: /bot984001690:AAHvJPz7H064B0J9CTJE-243qYMSOVhisPs/getUpdates (Caused by ConnectTimeoutError(<telegram.vendor.ptb_urllib3.urllib3.connection.VerifiedHTTPSConnection object at 0x0000016555AEE048>, 'Connection to api.telegram.org timed out. (connect timeout=5.0)'))\"\n",
      "2019-12-08 09:14:20,446 - telegram.vendor.ptb_urllib3.urllib3.connectionpool - WARNING - Retrying (Retry(total=2, connect=None, read=None, redirect=None)) after connection broken by 'ConnectTimeoutError(<telegram.vendor.ptb_urllib3.urllib3.connection.VerifiedHTTPSConnection object at 0x0000016555D85DC8>, 'Connection to api.telegram.org timed out. (connect timeout=5.0)')': /bot984001690:AAHvJPz7H064B0J9CTJE-243qYMSOVhisPs/getUpdates\n",
      "2019-12-08 09:14:25,453 - telegram.vendor.ptb_urllib3.urllib3.connectionpool - WARNING - Retrying (Retry(total=1, connect=None, read=None, redirect=None)) after connection broken by 'ConnectTimeoutError(<telegram.vendor.ptb_urllib3.urllib3.connection.VerifiedHTTPSConnection object at 0x0000016556007808>, 'Connection to api.telegram.org timed out. (connect timeout=5.0)')': /bot984001690:AAHvJPz7H064B0J9CTJE-243qYMSOVhisPs/getUpdates\n",
      "2019-12-08 09:14:30,460 - telegram.vendor.ptb_urllib3.urllib3.connectionpool - WARNING - Retrying (Retry(total=0, connect=None, read=None, redirect=None)) after connection broken by 'ConnectTimeoutError(<telegram.vendor.ptb_urllib3.urllib3.connection.VerifiedHTTPSConnection object at 0x0000016555AEE148>, 'Connection to api.telegram.org timed out. (connect timeout=5.0)')': /bot984001690:AAHvJPz7H064B0J9CTJE-243qYMSOVhisPs/getUpdates\n",
      "2019-12-08 09:14:35,472 - telegram.ext.updater - ERROR - Error while getting Updates: urllib3 HTTPError HTTPSConnectionPool(host='api.telegram.org', port=443): Max retries exceeded with url: /bot984001690:AAHvJPz7H064B0J9CTJE-243qYMSOVhisPs/getUpdates (Caused by ConnectTimeoutError(<telegram.vendor.ptb_urllib3.urllib3.connection.VerifiedHTTPSConnection object at 0x0000016555C50B08>, 'Connection to api.telegram.org timed out. (connect timeout=5.0)'))\n",
      "2019-12-08 09:14:35,472 - __main__ - WARNING - Update \"None\" caused error \"urllib3 HTTPError HTTPSConnectionPool(host='api.telegram.org', port=443): Max retries exceeded with url: /bot984001690:AAHvJPz7H064B0J9CTJE-243qYMSOVhisPs/getUpdates (Caused by ConnectTimeoutError(<telegram.vendor.ptb_urllib3.urllib3.connection.VerifiedHTTPSConnection object at 0x0000016555C50B08>, 'Connection to api.telegram.org timed out. (connect timeout=5.0)'))\"\n",
      "2019-12-08 09:15:10,494 - telegram.vendor.ptb_urllib3.urllib3.connectionpool - WARNING - Retrying (Retry(total=2, connect=None, read=None, redirect=None)) after connection broken by 'ConnectTimeoutError(<telegram.vendor.ptb_urllib3.urllib3.connection.VerifiedHTTPSConnection object at 0x0000016555B701C8>, 'Connection to api.telegram.org timed out. (connect timeout=5.0)')': /bot984001690:AAHvJPz7H064B0J9CTJE-243qYMSOVhisPs/getUpdates\n",
      "2019-12-08 09:15:15,501 - telegram.vendor.ptb_urllib3.urllib3.connectionpool - WARNING - Retrying (Retry(total=1, connect=None, read=None, redirect=None)) after connection broken by 'ConnectTimeoutError(<telegram.vendor.ptb_urllib3.urllib3.connection.VerifiedHTTPSConnection object at 0x000001655609C248>, 'Connection to api.telegram.org timed out. (connect timeout=5.0)')': /bot984001690:AAHvJPz7H064B0J9CTJE-243qYMSOVhisPs/getUpdates\n",
      "2019-12-08 09:15:20,503 - telegram.vendor.ptb_urllib3.urllib3.connectionpool - WARNING - Retrying (Retry(total=0, connect=None, read=None, redirect=None)) after connection broken by 'ConnectTimeoutError(<telegram.vendor.ptb_urllib3.urllib3.connection.VerifiedHTTPSConnection object at 0x0000016556007A08>, 'Connection to api.telegram.org timed out. (connect timeout=5.0)')': /bot984001690:AAHvJPz7H064B0J9CTJE-243qYMSOVhisPs/getUpdates\n",
      "2019-12-08 09:15:25,510 - telegram.ext.updater - ERROR - Error while getting Updates: urllib3 HTTPError HTTPSConnectionPool(host='api.telegram.org', port=443): Max retries exceeded with url: /bot984001690:AAHvJPz7H064B0J9CTJE-243qYMSOVhisPs/getUpdates (Caused by ConnectTimeoutError(<telegram.vendor.ptb_urllib3.urllib3.connection.VerifiedHTTPSConnection object at 0x000001655609CC48>, 'Connection to api.telegram.org timed out. (connect timeout=5.0)'))\n",
      "2019-12-08 09:15:25,510 - __main__ - WARNING - Update \"None\" caused error \"urllib3 HTTPError HTTPSConnectionPool(host='api.telegram.org', port=443): Max retries exceeded with url: /bot984001690:AAHvJPz7H064B0J9CTJE-243qYMSOVhisPs/getUpdates (Caused by ConnectTimeoutError(<telegram.vendor.ptb_urllib3.urllib3.connection.VerifiedHTTPSConnection object at 0x000001655609CC48>, 'Connection to api.telegram.org timed out. (connect timeout=5.0)'))\"\n",
      "2019-12-09 16:25:09,290 - telegram.ext.updater - INFO - Received signal 2 (SIGINT), stopping...\n"
     ]
    }
   ],
   "source": [
    "import logging\n",
    "\n",
    "import re\n",
    "\n",
    "from telegram import ReplyKeyboardMarkup\n",
    "from telegram.ext import (Updater, CommandHandler, MessageHandler, Filters,\n",
    "                          ConversationHandler)\n",
    "\n",
    "# Enable logging\n",
    "logging.basicConfig(format='%(asctime)s - %(name)s - %(levelname)s - %(message)s',\n",
    "                    level=logging.INFO)\n",
    "\n",
    "logger = logging.getLogger(__name__)\n",
    "\n",
    "CHOOSING, STEP_2_FIND_SPEC , CHOOSE_AGE, PROBLEM_CATEGORY, QUESTION_CATEGORY = range(5)\n",
    "FIND_SPEC_NOW, CHOOSING_ABOUT = range(5,7)\n",
    "\n",
    "\n",
    "\n",
    "def start(update, context):\n",
    "    reply_keyboard = [['Найти специалиста', 'О сервисе']]\n",
    "\n",
    "    markup = ReplyKeyboardMarkup(reply_keyboard, one_time_keyboard=True)\n",
    "    update.message.reply_text(\n",
    "        \"\"\"Привет! Этот бот поможет тебе справиться с депрессией или другими психологическими проблемами, которые тебя беспокоят! \n",
    "        Давай начнем: выбери \"Найти специалиста\" или узнай о нас больше выбрав \"О сервисе\", \n",
    "        так же ты можешь выбрать быструю помощь и мы найдем тебе ближайшего освободившегося специалиста\"\"\",\n",
    "        reply_markup=markup)\n",
    "\n",
    "    return CHOOSING\n",
    "\n",
    "def stop(update, context):\n",
    "    \"\"\"Закончить общение с ботом по команде /stop\"\"\"\n",
    "    update.message.reply_text(\"\"\"Пока!\"\"\")\n",
    "    \n",
    "    return ConversationHandler.END\n",
    "\n",
    "def done(update, context):\n",
    "    update.message.reply_text(\"\"\"Пока!\"\"\")\n",
    "    user_data = context.user_data\n",
    "    if 'choice' in user_data:\n",
    "        del user_data['choice']\n",
    "\n",
    "    print(user_data)\n",
    "\n",
    "    user_data.clear()\n",
    "    return ConversationHandler.END\n",
    "\n",
    "def Find_Spec(update, context):\n",
    "    r\"\"\"найи специалиста выбор из двух альтернатив и переход к след шагу\"\"\"\n",
    "    reply_keyboard_loc = [['Быстрая помощь','Подобрать', 'Список Специалистов']]\n",
    "\n",
    "    markup_loc = ReplyKeyboardMarkup(reply_keyboard_loc, one_time_keyboard=True)\n",
    "    \n",
    "    update.message.reply_text(\n",
    "        \"\"\"Мы можем помочь подобрать Вам специалиста сразу или в зависимости от характера вашей проблемы, \n",
    "        либо вы можете выбрать его самостоятельно из списка специалистов.\"\"\",\n",
    "        reply_markup=markup_loc)\n",
    "    \n",
    "    return STEP_2_FIND_SPEC\n",
    "\n",
    "def Pol(update, context):\n",
    "    r\"\"\"Пол\"\"\"\n",
    "    reply_keyboard_loc = [['М', 'Ж']]\n",
    "    markup_loc = ReplyKeyboardMarkup(reply_keyboard_loc, one_time_keyboard=True)\n",
    "    \n",
    "    update.message.reply_text(\"\"\"Выберите ваш пол.\"\"\", reply_markup=markup_loc)\n",
    "    return CHOOSE_AGE\n",
    "\n",
    "\n",
    "def Age(update, context):\n",
    "    r\"\"\"Возраст\"\"\"\n",
    "    reply_keyboard_loc = [['< 16', '16-22', '22-40', \"> 40\"]]\n",
    "    markup_loc = ReplyKeyboardMarkup(reply_keyboard_loc, one_time_keyboard=True)\n",
    "    update.message.reply_text(\"\"\"Выберите ваш возраст.\"\"\", reply_markup=markup_loc)\n",
    "    \n",
    "    return PROBLEM_CATEGORY\n",
    "\n",
    "def Problem_Category(update, context):\n",
    "    r\"\"\"Выбрать проблему из предложенных типов\"\"\"\n",
    "    reply_keyboard_loc = [['Семья', 'Друзья', 'Отношения', \"Работа\", \"Учеба\", \"Другое\"]]\n",
    "    markup_loc = ReplyKeyboardMarkup(reply_keyboard_loc, one_time_keyboard=True)\n",
    "    update.message.reply_text(\"\"\"К какой категории Вы могли бы отнести свою психологическую проблему?\"\"\", reply_markup=markup_loc)\n",
    "    \n",
    "    return QUESTION_CATEGORY\n",
    "\n",
    "def Question_Category(update, context):\n",
    "    r\"\"\"Выбрать вопрос из предложенных типов\"\"\"\n",
    "    reply_keyboard_loc = [['Я запутался/лась', 'Мне не интересно или скучно', 'Я устал', \"Меня никто не слушает\",\n",
    "                           \"Что делать дальше\", \"Как сделать правильный выбор\", \"Другое\"]]\n",
    "    markup_loc = ReplyKeyboardMarkup(reply_keyboard_loc, one_time_keyboard=True)\n",
    "    update.message.reply_text(\"\"\"Какие утверждения или вопросы подходят Вам наиболее всего?\"\"\", reply_markup=markup_loc)\n",
    "    \n",
    "    return WAITING_TIME\n",
    "\n",
    "def find_spec_now(update, contex):\n",
    "    r\"\"\"Подбор специалиста сразу\"\"\"\n",
    "    update.message.reply_text(\"\"\"Мы уже ищем специалиста. Ожидайте...\"\"\")\n",
    "    ''' Нужно допилить алгоритм быстрого поиска'''\n",
    "    def fast_search(update, context):\n",
    "        pass\n",
    "    \n",
    "    return FIND_SPEC_NOW\n",
    "\n",
    "def about(update, context):\n",
    "    r\"\"\"О нас\"\"\"\n",
    "    reply_keyboard_loc = [['О сервисе', 'Стоимость услуг', 'Отзывы', \"О нас пишут\", \"FAQ\" ]]\n",
    "    markup_loc = ReplyKeyboardMarkup(reply_keyboard_loc, one_time_keyboard=True)\n",
    "    update.message.reply_text(\"\"\"PsyHelp - бот психологической поддержки\"\"\", reply_markup=markup_loc)\n",
    "    \n",
    "    return CHOOSING_ABOUT\n",
    "    \n",
    "def error(update, context):\n",
    "    \"\"\"Log Errors caused by Updates.\"\"\"\n",
    "    logger.warning('Update \"%s\" caused error \"%s\"', update, context.error)\n",
    "\n",
    "\n",
    "def main():\n",
    "    # Create the Updater and pass it your bot's token.\n",
    "    # Make sure to set use_context=True to use the new context based callbacks\n",
    "    # Post version 12 this will no longer be necessary\n",
    "    updater = Updater(\"984001690:AAHvJPz7H064B0J9CTJE-243qYMSOVhisPs\", use_context=True)\n",
    "\n",
    "    # Get the dispatcher to register handlers\n",
    "    dp = updater.dispatcher\n",
    "\n",
    "    # Add conversation handler with the states CHOOSING, TYPING_CHOICE and TYPING_REPLY\n",
    "    conv_handler = ConversationHandler(\n",
    "        entry_points=[CommandHandler('start', start)],\n",
    "\n",
    "        states={\n",
    "            CHOOSING: [MessageHandler(Filters.regex('^Найти специалиста$'),\n",
    "                                      Find_Spec),\n",
    "                       MessageHandler(Filters.regex('^О сервисе$'),\n",
    "                                      about),\n",
    "                       ],\n",
    "            STEP_2_FIND_SPEC: [ MessageHandler(Filters.regex('^Быстрая помощь$'),\n",
    "                                      find_spec_now),\n",
    "                               MessageHandler(Filters.regex('^Подобрать$'),\n",
    "                                      Pol),\n",
    "                       MessageHandler(Filters.regex('^Список Специалистов$'),\n",
    "                                      Pol)\n",
    "            ],\n",
    "\n",
    "            CHOOSE_AGE: [MessageHandler(Filters.regex('^.*$'), Age) \n",
    "                            ],\n",
    "            \n",
    "            PROBLEM_CATEGORY: [MessageHandler(Filters.regex('^.*$'), Problem_Category)\n",
    "                            ],\n",
    "            \n",
    "            QUESTION_CATEGORY: [MessageHandler(Filters.regex('^.*$'), Question_Category)\n",
    "                            ],\n",
    "        },\n",
    "\n",
    "        fallbacks=[MessageHandler(Filters.regex('^Done$'), done),\n",
    "                  CommandHandler('stop', stop)]\n",
    "    )\n",
    "\n",
    "    dp.add_handler(conv_handler)\n",
    "\n",
    "    # log all errors\n",
    "    dp.add_error_handler(error)\n",
    "\n",
    "    # Start the Bot\n",
    "    updater.start_polling()\n",
    "\n",
    "    # Run the bot until you press Ctrl-C or the process receives SIGINT,\n",
    "    # SIGTERM or SIGABRT. This should be used most of the time, since\n",
    "    # start_polling() is non-blocking and will stop the bot gracefully.\n",
    "    updater.idle()\n",
    "\n",
    "\n",
    "if __name__ == '__main__':\n",
    "    main()"
   ]
  },
  {
   "cell_type": "code",
   "execution_count": null,
   "metadata": {},
   "outputs": [],
   "source": []
  }
 ],
 "metadata": {
  "kernelspec": {
   "display_name": "Python 3",
   "language": "python",
   "name": "python3"
  },
  "language_info": {
   "codemirror_mode": {
    "name": "ipython",
    "version": 3
   },
   "file_extension": ".py",
   "mimetype": "text/x-python",
   "name": "python",
   "nbconvert_exporter": "python",
   "pygments_lexer": "ipython3",
   "version": "3.7.4"
  }
 },
 "nbformat": 4,
 "nbformat_minor": 2
}
